Traceback (most recent call last):
  File "/Library/Frameworks/Python.framework/Versions/3.7/lib/python3.7/site-packages/jupyter_cache/executors/utils.py", line 56, in single_nb_execution
    record_timing=False,
  File "/Library/Frameworks/Python.framework/Versions/3.7/lib/python3.7/site-packages/nbclient/client.py", line 1112, in execute
    return NotebookClient(nb=nb, resources=resources, km=km, **kwargs).execute()
  File "/Library/Frameworks/Python.framework/Versions/3.7/lib/python3.7/site-packages/nbclient/util.py", line 74, in wrapped
    return just_run(coro(*args, **kwargs))
  File "/Library/Frameworks/Python.framework/Versions/3.7/lib/python3.7/site-packages/nbclient/util.py", line 53, in just_run
    return loop.run_until_complete(coro)
  File "/Library/Frameworks/Python.framework/Versions/3.7/lib/python3.7/asyncio/base_events.py", line 587, in run_until_complete
    return future.result()
  File "/Library/Frameworks/Python.framework/Versions/3.7/lib/python3.7/site-packages/nbclient/client.py", line 554, in async_execute
    cell, index, execution_count=self.code_cells_executed + 1
  File "/Library/Frameworks/Python.framework/Versions/3.7/lib/python3.7/site-packages/nbclient/client.py", line 857, in async_execute_cell
    self._check_raise_for_error(cell, exec_reply)
  File "/Library/Frameworks/Python.framework/Versions/3.7/lib/python3.7/site-packages/nbclient/client.py", line 760, in _check_raise_for_error
    raise CellExecutionError.from_cell_and_msg(cell, exec_reply_content)
nbclient.exceptions.CellExecutionError: An error occurred while executing the following cell:
------------------
#----
#calculo num√©rico
import numpy as np   # importar a biblioteca Numpy para lidar com matrizes
import pandas as pd   # importa bilioteca pandas para  lidar com processamento de dados
from scipy.optimize import curve_fit # pacote para ajuste de curvas
#----
#navegar pelo sistema de arquivos
import os #com
import glob
#---
#desenhar circuitos
import SchemDraw as schem
import SchemDraw.elements as e
#----
#pacote para gr√°ficos interativos
import plotly.graph_objects as go
from plotly.subplots import make_subplots
from plotly.offline import  init_notebook_mode 
init_notebook_mode(connected=True)
------------------

[0;31m---------------------------------------------------------------------------[0m
[0;31mModuleNotFoundError[0m                       Traceback (most recent call last)
[0;32m<ipython-input-1-ac244093e7ab>[0m in [0;36m<module>[0;34m[0m
[1;32m     14[0m [0;31m#----[0m[0;34m[0m[0;34m[0m[0;34m[0m[0m
[1;32m     15[0m [0;31m#pacote para gr√°ficos interativos[0m[0;34m[0m[0;34m[0m[0;34m[0m[0m
[0;32m---> 16[0;31m [0;32mimport[0m [0mplotly[0m[0;34m.[0m[0mgraph_objects[0m [0;32mas[0m [0mgo[0m[0;34m[0m[0;34m[0m[0m
[0m[1;32m     17[0m [0;32mfrom[0m [0mplotly[0m[0;34m.[0m[0msubplots[0m [0;32mimport[0m [0mmake_subplots[0m[0;34m[0m[0;34m[0m[0m
[1;32m     18[0m [0;32mfrom[0m [0mplotly[0m[0;34m.[0m[0moffline[0m [0;32mimport[0m  [0minit_notebook_mode[0m[0;34m[0m[0;34m[0m[0m

[0;31mModuleNotFoundError[0m: No module named 'plotly'
ModuleNotFoundError: No module named 'plotly'

