Traceback (most recent call last):
  File "/Library/Frameworks/Python.framework/Versions/3.7/lib/python3.7/site-packages/jupyter_cache/executors/utils.py", line 56, in single_nb_execution
    record_timing=False,
  File "/Library/Frameworks/Python.framework/Versions/3.7/lib/python3.7/site-packages/nbclient/client.py", line 1112, in execute
    return NotebookClient(nb=nb, resources=resources, km=km, **kwargs).execute()
  File "/Library/Frameworks/Python.framework/Versions/3.7/lib/python3.7/site-packages/nbclient/util.py", line 74, in wrapped
    return just_run(coro(*args, **kwargs))
  File "/Library/Frameworks/Python.framework/Versions/3.7/lib/python3.7/site-packages/nbclient/util.py", line 53, in just_run
    return loop.run_until_complete(coro)
  File "/Library/Frameworks/Python.framework/Versions/3.7/lib/python3.7/asyncio/base_events.py", line 587, in run_until_complete
    return future.result()
  File "/Library/Frameworks/Python.framework/Versions/3.7/lib/python3.7/site-packages/nbclient/client.py", line 554, in async_execute
    cell, index, execution_count=self.code_cells_executed + 1
  File "/Library/Frameworks/Python.framework/Versions/3.7/lib/python3.7/site-packages/nbclient/client.py", line 857, in async_execute_cell
    self._check_raise_for_error(cell, exec_reply)
  File "/Library/Frameworks/Python.framework/Versions/3.7/lib/python3.7/site-packages/nbclient/client.py", line 760, in _check_raise_for_error
    raise CellExecutionError.from_cell_and_msg(cell, exec_reply_content)
nbclient.exceptions.CellExecutionError: An error occurred while executing the following cell:
------------------
#****************************
# Setting up plot configurations
# Configurando gr√°ficos
#****************************
#Adjusting fonts pattern
#Ajsutando fontes padr√£o dos gr√°ficos
font = { 'weight' : 'normal',
        'size'   : 12}

plt.rc('font', **font)
#Ajsutando espessura das linhas padr√£o dos gr√°ficos
plt.rcParams['lines.linewidth'] = 2;
plt.locator_params(nticks=4)
------------------

[0;31m---------------------------------------------------------------------------[0m
[0;31mTypeError[0m                                 Traceback (most recent call last)
[0;32m<ipython-input-18-c0c524b1c9f2>[0m in [0;36m<module>[0;34m[0m
[1;32m     11[0m [0;31m#Ajsutando espessura das linhas padr√£o dos gr√°ficos[0m[0;34m[0m[0;34m[0m[0;34m[0m[0m
[1;32m     12[0m [0mplt[0m[0;34m.[0m[0mrcParams[0m[0;34m[[0m[0;34m'lines.linewidth'[0m[0;34m][0m [0;34m=[0m [0;36m2[0m[0;34m;[0m[0;34m[0m[0;34m[0m[0m
[0;32m---> 13[0;31m [0mplt[0m[0;34m.[0m[0mlocator_params[0m[0;34m([0m[0mnticks[0m[0;34m=[0m[0;36m4[0m[0;34m)[0m[0;34m[0m[0;34m[0m[0m
[0m
[0;32m/Library/Frameworks/Python.framework/Versions/3.7/lib/python3.7/site-packages/matplotlib/pyplot.py[0m in [0;36mlocator_params[0;34m(axis, tight, **kwargs)[0m
[1;32m   2742[0m [0;34m@[0m[0m_copy_docstring_and_deprecators[0m[0;34m([0m[0mAxes[0m[0;34m.[0m[0mlocator_params[0m[0;34m)[0m[0;34m[0m[0;34m[0m[0m
[1;32m   2743[0m [0;32mdef[0m [0mlocator_params[0m[0;34m([0m[0maxis[0m[0;34m=[0m[0;34m'both'[0m[0;34m,[0m [0mtight[0m[0;34m=[0m[0;32mNone[0m[0;34m,[0m [0;34m**[0m[0mkwargs[0m[0;34m)[0m[0;34m:[0m[0;34m[0m[0;34m[0m[0m
[0;32m-> 2744[0;31m     [0;32mreturn[0m [0mgca[0m[0;34m([0m[0;34m)[0m[0;34m.[0m[0mlocator_params[0m[0;34m([0m[0maxis[0m[0;34m=[0m[0maxis[0m[0;34m,[0m [0mtight[0m[0;34m=[0m[0mtight[0m[0;34m,[0m [0;34m**[0m[0mkwargs[0m[0;34m)[0m[0;34m[0m[0;34m[0m[0m
[0m[1;32m   2745[0m [0;34m[0m[0m
[1;32m   2746[0m [0;34m[0m[0m

[0;32m/Library/Frameworks/Python.framework/Versions/3.7/lib/python3.7/site-packages/matplotlib/axes/_base.py[0m in [0;36mlocator_params[0;34m(self, axis, tight, **kwargs)[0m
[1;32m   3006[0m         [0mupdate_y[0m [0;34m=[0m [0maxis[0m [0;32min[0m [0;34m[[0m[0;34m'y'[0m[0;34m,[0m [0;34m'both'[0m[0;34m][0m[0;34m[0m[0;34m[0m[0m
[1;32m   3007[0m         [0;32mif[0m [0mupdate_x[0m[0;34m:[0m[0;34m[0m[0;34m[0m[0m
[0;32m-> 3008[0;31m             [0mself[0m[0;34m.[0m[0mxaxis[0m[0;34m.[0m[0mget_major_locator[0m[0;34m([0m[0;34m)[0m[0;34m.[0m[0mset_params[0m[0;34m([0m[0;34m**[0m[0mkwargs[0m[0;34m)[0m[0;34m[0m[0;34m[0m[0m
[0m[1;32m   3009[0m         [0;32mif[0m [0mupdate_y[0m[0;34m:[0m[0;34m[0m[0;34m[0m[0m
[1;32m   3010[0m             [0mself[0m[0;34m.[0m[0myaxis[0m[0;34m.[0m[0mget_major_locator[0m[0;34m([0m[0;34m)[0m[0;34m.[0m[0mset_params[0m[0;34m([0m[0;34m**[0m[0mkwargs[0m[0;34m)[0m[0;34m[0m[0;34m[0m[0m

[0;32m/Library/Frameworks/Python.framework/Versions/3.7/lib/python3.7/site-packages/matplotlib/ticker.py[0m in [0;36mset_params[0;34m(self, **kwargs)[0m
[1;32m   2210[0m             [0mkey[0m[0;34m,[0m [0m_[0m [0;34m=[0m [0mkwargs[0m[0;34m.[0m[0mpopitem[0m[0;34m([0m[0;34m)[0m[0;34m[0m[0;34m[0m[0m
[1;32m   2211[0m             raise TypeError(
[0;32m-> 2212[0;31m                 f"set_params() got an unexpected keyword argument '{key}'")
[0m[1;32m   2213[0m [0;34m[0m[0m
[1;32m   2214[0m     [0;32mdef[0m [0m_raw_ticks[0m[0;34m([0m[0mself[0m[0;34m,[0m [0mvmin[0m[0;34m,[0m [0mvmax[0m[0;34m)[0m[0;34m:[0m[0;34m[0m[0;34m[0m[0m

[0;31mTypeError[0m: set_params() got an unexpected keyword argument 'nticks'
TypeError: set_params() got an unexpected keyword argument 'nticks'

