Traceback (most recent call last):
  File "/Library/Frameworks/Python.framework/Versions/3.7/lib/python3.7/site-packages/jupyter_cache/executors/utils.py", line 56, in single_nb_execution
    record_timing=False,
  File "/Library/Frameworks/Python.framework/Versions/3.7/lib/python3.7/site-packages/nbclient/client.py", line 1112, in execute
    return NotebookClient(nb=nb, resources=resources, km=km, **kwargs).execute()
  File "/Library/Frameworks/Python.framework/Versions/3.7/lib/python3.7/site-packages/nbclient/util.py", line 74, in wrapped
    return just_run(coro(*args, **kwargs))
  File "/Library/Frameworks/Python.framework/Versions/3.7/lib/python3.7/site-packages/nbclient/util.py", line 53, in just_run
    return loop.run_until_complete(coro)
  File "/Library/Frameworks/Python.framework/Versions/3.7/lib/python3.7/asyncio/base_events.py", line 587, in run_until_complete
    return future.result()
  File "/Library/Frameworks/Python.framework/Versions/3.7/lib/python3.7/site-packages/nbclient/client.py", line 554, in async_execute
    cell, index, execution_count=self.code_cells_executed + 1
  File "/Library/Frameworks/Python.framework/Versions/3.7/lib/python3.7/site-packages/nbclient/client.py", line 857, in async_execute_cell
    self._check_raise_for_error(cell, exec_reply)
  File "/Library/Frameworks/Python.framework/Versions/3.7/lib/python3.7/site-packages/nbclient/client.py", line 760, in _check_raise_for_error
    raise CellExecutionError.from_cell_and_msg(cell, exec_reply_content)
nbclient.exceptions.CellExecutionError: An error occurred while executing the following cell:
------------------
#Loading dataset with "tab" as separator
path='dados'
filename = 'dados_Vce_Vcc_15p5.csv'
filepath = os.path.join(path,filename)
df = pd.read_csv(filepath) #DataFrame
glue("df_pandas_ic_vce", data.head())
#---
filename = 'dados_Ic_vs_Ib_Vbb_Vcc_15p5V.csv'
filepath = os.path.join(path,filename)
df = pd.read_csv(filepath) #DataFrame
glue("df_pandas_beta", data.head())
------------------

[0;31m---------------------------------------------------------------------------[0m
[0;31mNameError[0m                                 Traceback (most recent call last)
[0;32m<ipython-input-2-ae2962ec3c3e>[0m in [0;36m<module>[0;34m[0m
[1;32m      4[0m [0mfilepath[0m [0;34m=[0m [0mos[0m[0;34m.[0m[0mpath[0m[0;34m.[0m[0mjoin[0m[0;34m([0m[0mpath[0m[0;34m,[0m[0mfilename[0m[0;34m)[0m[0;34m[0m[0;34m[0m[0m
[1;32m      5[0m [0mdf[0m [0;34m=[0m [0mpd[0m[0;34m.[0m[0mread_csv[0m[0;34m([0m[0mfilepath[0m[0;34m)[0m [0;31m#DataFrame[0m[0;34m[0m[0;34m[0m[0m
[0;32m----> 6[0;31m [0mglue[0m[0;34m([0m[0;34m"df_pandas_ic_vce"[0m[0;34m,[0m [0mdata[0m[0;34m.[0m[0mhead[0m[0;34m([0m[0;34m)[0m[0;34m)[0m[0;34m[0m[0;34m[0m[0m
[0m[1;32m      7[0m [0;31m#---[0m[0;34m[0m[0;34m[0m[0;34m[0m[0m
[1;32m      8[0m [0mfilename[0m [0;34m=[0m [0;34m'dados_Ic_vs_Ib_Vbb_Vcc_15p5V.csv'[0m[0;34m[0m[0;34m[0m[0m

[0;31mNameError[0m: name 'data' is not defined
NameError: name 'data' is not defined

