Traceback (most recent call last):
  File "/Library/Frameworks/Python.framework/Versions/3.7/lib/python3.7/site-packages/jupyter_cache/executors/utils.py", line 56, in single_nb_execution
    record_timing=False,
  File "/Library/Frameworks/Python.framework/Versions/3.7/lib/python3.7/site-packages/nbclient/client.py", line 1112, in execute
    return NotebookClient(nb=nb, resources=resources, km=km, **kwargs).execute()
  File "/Library/Frameworks/Python.framework/Versions/3.7/lib/python3.7/site-packages/nbclient/util.py", line 74, in wrapped
    return just_run(coro(*args, **kwargs))
  File "/Library/Frameworks/Python.framework/Versions/3.7/lib/python3.7/site-packages/nbclient/util.py", line 53, in just_run
    return loop.run_until_complete(coro)
  File "/Library/Frameworks/Python.framework/Versions/3.7/lib/python3.7/asyncio/base_events.py", line 587, in run_until_complete
    return future.result()
  File "/Library/Frameworks/Python.framework/Versions/3.7/lib/python3.7/site-packages/nbclient/client.py", line 554, in async_execute
    cell, index, execution_count=self.code_cells_executed + 1
  File "/Library/Frameworks/Python.framework/Versions/3.7/lib/python3.7/site-packages/nbclient/client.py", line 857, in async_execute_cell
    self._check_raise_for_error(cell, exec_reply)
  File "/Library/Frameworks/Python.framework/Versions/3.7/lib/python3.7/site-packages/nbclient/client.py", line 760, in _check_raise_for_error
    raise CellExecutionError.from_cell_and_msg(cell, exec_reply_content)
nbclient.exceptions.CellExecutionError: An error occurred while executing the following cell:
------------------
func_gen = pylef.BK4052()          # defini√ß√£o do gerador de fun√ß√µes
scope = pylef.TektronixTBS1062()   # defini√ß√£o do oscilosc√≥pio
------------------

[0;31m---------------------------------------------------------------------------[0m
[0;31mValueError[0m                                Traceback (most recent call last)
[0;32m<ipython-input-3-9492673a926d>[0m in [0;36m<module>[0;34m[0m
[1;32m      1[0m [0mfunc_gen[0m [0;34m=[0m [0mpylef[0m[0;34m.[0m[0mBK4052[0m[0;34m([0m[0;34m)[0m          [0;31m# defini√ß√£o do gerador de fun√ß√µes[0m[0;34m[0m[0;34m[0m[0m
[0;32m----> 2[0;31m [0mscope[0m [0;34m=[0m [0mpylef[0m[0;34m.[0m[0mTektronixTBS1062[0m[0;34m([0m[0;34m)[0m   [0;31m# defini√ß√£o do oscilosc√≥pio[0m[0;34m[0m[0;34m[0m[0m
[0m
[0;32m/Library/Frameworks/Python.framework/Versions/3.7/lib/python3.7/site-packages/pylef/scope.py[0m in [0;36m__init__[0;34m(self)[0m
[1;32m     43[0m         """
[1;32m     44[0m         [0mself[0m[0;34m.[0m[0mid_tek[0m [0;34m=[0m [0;34m'0x0699'[0m[0;34m;[0m [0;31m# identificador do fabricante TEK[0m[0;34m[0m[0;34m[0m[0m
[0;32m---> 45[0;31m         [0minterface_name[0m [0;34m=[0m [0mself[0m[0;34m.[0m[0mfind_interface[0m[0;34m([0m[0;34m)[0m[0;34m[0m[0;34m[0m[0m
[0m[1;32m     46[0m         [0mself[0m[0;34m.[0m[0minstr[0m [0;34m=[0m [0mvisa[0m[0;34m.[0m[0mResourceManager[0m[0;34m([0m[0;34m)[0m[0;34m.[0m[0mopen_resource[0m[0;34m([0m[0minterface_name[0m[0;34m)[0m   [0;31m## resource name[0m[0;34m[0m[0;34m[0m[0m
[1;32m     47[0m         [0mself[0m[0;34m.[0m[0mdelay_time[0m [0;34m=[0m [0;36m0.1[0m [0;31m# time to wait after write and query - BK BUG![0m[0;34m[0m[0;34m[0m[0m

[0;32m/Library/Frameworks/Python.framework/Versions/3.7/lib/python3.7/site-packages/pylef/scope.py[0m in [0;36mfind_interface[0;34m(self)[0m
[1;32m     82[0m                 [0mprint[0m[0;34m([0m[0;34m"Oscilosc√≥pio conectado! Id = "[0m [0;34m+[0m [0mtek_str[0m[0;34m[[0m[0;34m:[0m[0;34m-[0m[0;36m1[0m[0;34m][0m[0;34m)[0m[0;34m[0m[0;34m[0m[0m
[1;32m     83[0m         [0;32mif[0m [0mtek_str[0m [0;34m==[0m [0;34m''[0m[0;34m:[0m[0;34m[0m[0;34m[0m[0m
[0;32m---> 84[0;31m             raise ValueError('O osciloscopio TEK 1062 nao foi identificado:\n'\
[0m[1;32m     85[0m                          [0;34m'Verique se o equipamento est√° ligado e se o cabo USB \n'[0m[0;31m\[0m[0;34m[0m[0;34m[0m[0m
[1;32m     86[0m                          [0;34m'foi conectado. Se o problema persistir, \n'[0m[0;31m\[0m[0;34m[0m[0;34m[0m[0m

[0;31mValueError[0m: O osciloscopio TEK 1062 nao foi identificado:
Verique se o equipamento est√° ligado e se o cabo USB 
foi conectado. Se o problema persistir, 
desconecte o cabo USB, aguarde 20 segundos 
e conecte novamente.
ValueError: O osciloscopio TEK 1062 nao foi identificado:
Verique se o equipamento est√° ligado e se o cabo USB 
foi conectado. Se o problema persistir, 
desconecte o cabo USB, aguarde 20 segundos 
e conecte novamente.

