Traceback (most recent call last):
  File "/Library/Frameworks/Python.framework/Versions/3.7/lib/python3.7/site-packages/jupyter_cache/executors/utils.py", line 56, in single_nb_execution
    record_timing=False,
  File "/Library/Frameworks/Python.framework/Versions/3.7/lib/python3.7/site-packages/nbclient/client.py", line 1112, in execute
    return NotebookClient(nb=nb, resources=resources, km=km, **kwargs).execute()
  File "/Library/Frameworks/Python.framework/Versions/3.7/lib/python3.7/site-packages/nbclient/util.py", line 74, in wrapped
    return just_run(coro(*args, **kwargs))
  File "/Library/Frameworks/Python.framework/Versions/3.7/lib/python3.7/site-packages/nbclient/util.py", line 53, in just_run
    return loop.run_until_complete(coro)
  File "/Library/Frameworks/Python.framework/Versions/3.7/lib/python3.7/asyncio/base_events.py", line 587, in run_until_complete
    return future.result()
  File "/Library/Frameworks/Python.framework/Versions/3.7/lib/python3.7/site-packages/nbclient/client.py", line 554, in async_execute
    cell, index, execution_count=self.code_cells_executed + 1
  File "/Library/Frameworks/Python.framework/Versions/3.7/lib/python3.7/site-packages/nbclient/client.py", line 857, in async_execute_cell
    self._check_raise_for_error(cell, exec_reply)
  File "/Library/Frameworks/Python.framework/Versions/3.7/lib/python3.7/site-packages/nbclient/client.py", line 760, in _check_raise_for_error
    raise CellExecutionError.from_cell_and_msg(cell, exec_reply_content)
nbclient.exceptions.CellExecutionError: An error occurred while executing the following cell:
------------------
eq2 = [Eq(coef,0) for coef in coefs]
solution, = linsolve(eq2,(i0,theta))
------------------

[0;31m---------------------------------------------------------------------------[0m
[0;31mKeyError[0m                                  Traceback (most recent call last)
[0;32m/Library/Frameworks/Python.framework/Versions/3.7/lib/python3.7/site-packages/sympy-1.7.1-py3.7.egg/sympy/polys/polyutils.py[0m in [0;36m_parallel_dict_from_expr_if_gens[0;34m(exprs, opt)[0m
[1;32m    209[0m [0;34m[0m[0m
[0;32m--> 210[0;31m                         [0mmonom[0m[0;34m[[0m[0mindices[0m[0;34m[[0m[0mbase[0m[0;34m][0m[0;34m][0m [0;34m=[0m [0mexp[0m[0;34m[0m[0;34m[0m[0m
[0m[1;32m    211[0m                     [0;32mexcept[0m [0mKeyError[0m[0;34m:[0m[0;34m[0m[0;34m[0m[0m

[0;31mKeyError[0m: cos(theta)

During handling of the above exception, another exception occurred:

[0;31mPolynomialError[0m                           Traceback (most recent call last)
[0;32m/Library/Frameworks/Python.framework/Versions/3.7/lib/python3.7/site-packages/sympy-1.7.1-py3.7.egg/sympy/solvers/solveset.py[0m in [0;36mlinsolve[0;34m(system, *symbols)[0m
[1;32m   2638[0m             [0;32mtry[0m[0;34m:[0m[0;34m[0m[0;34m[0m[0m
[0;32m-> 2639[0;31m                 [0meqs[0m[0;34m,[0m [0mring[0m [0;34m=[0m [0msympy_eqs_to_ring[0m[0;34m([0m[0meqs[0m[0;34m,[0m [0msymbols[0m[0;34m)[0m[0;34m[0m[0;34m[0m[0m
[0m[1;32m   2640[0m             [0;32mexcept[0m [0mPolynomialError[0m [0;32mas[0m [0mexc[0m[0;34m:[0m[0;34m[0m[0;34m[0m[0m

[0;32m/Library/Frameworks/Python.framework/Versions/3.7/lib/python3.7/site-packages/sympy-1.7.1-py3.7.egg/sympy/polys/solvers.py[0m in [0;36msympy_eqs_to_ring[0;34m(eqs, symbols)[0m
[1;32m    127[0m     [0;32mtry[0m[0;34m:[0m[0;34m[0m[0;34m[0m[0m
[0;32m--> 128[0;31m         [0mK[0m[0;34m,[0m [0meqs_K[0m [0;34m=[0m [0msring[0m[0;34m([0m[0meqs[0m[0;34m,[0m [0msymbols[0m[0;34m,[0m [0mfield[0m[0;34m=[0m[0;32mTrue[0m[0;34m,[0m [0mextension[0m[0;34m=[0m[0;32mTrue[0m[0;34m)[0m[0;34m[0m[0;34m[0m[0m
[0m[1;32m    129[0m     [0;32mexcept[0m [0mNotInvertible[0m[0;34m:[0m[0;34m[0m[0;34m[0m[0m

[0;32m/Library/Frameworks/Python.framework/Versions/3.7/lib/python3.7/site-packages/sympy-1.7.1-py3.7.egg/sympy/polys/rings.py[0m in [0;36msring[0;34m(exprs, *symbols, **options)[0m
[1;32m    162[0m     [0;31m# TODO: rewrite this so that it doesn't use expand() (see poly()).[0m[0;34m[0m[0;34m[0m[0;34m[0m[0m
[0;32m--> 163[0;31m     [0mreps[0m[0;34m,[0m [0mopt[0m [0;34m=[0m [0m_parallel_dict_from_expr[0m[0;34m([0m[0mexprs[0m[0;34m,[0m [0mopt[0m[0;34m)[0m[0;34m[0m[0;34m[0m[0m
[0m[1;32m    164[0m [0;34m[0m[0m

[0;32m/Library/Frameworks/Python.framework/Versions/3.7/lib/python3.7/site-packages/sympy-1.7.1-py3.7.egg/sympy/polys/polyutils.py[0m in [0;36m_parallel_dict_from_expr[0;34m(exprs, opt)[0m
[1;32m    330[0m     [0;32mif[0m [0mopt[0m[0;34m.[0m[0mgens[0m[0;34m:[0m[0;34m[0m[0;34m[0m[0m
[0;32m--> 331[0;31m         [0mreps[0m[0;34m,[0m [0mgens[0m [0;34m=[0m [0m_parallel_dict_from_expr_if_gens[0m[0;34m([0m[0mexprs[0m[0;34m,[0m [0mopt[0m[0;34m)[0m[0;34m[0m[0;34m[0m[0m
[0m[1;32m    332[0m     [0;32melse[0m[0;34m:[0m[0;34m[0m[0;34m[0m[0m

[0;32m/Library/Frameworks/Python.framework/Versions/3.7/lib/python3.7/site-packages/sympy-1.7.1-py3.7.egg/sympy/polys/polyutils.py[0m in [0;36m_parallel_dict_from_expr_if_gens[0;34m(exprs, opt)[0m
[1;32m    215[0m                             raise PolynomialError("%s contains an element of "
[0;32m--> 216[0;31m                                                   "the set of generators." % factor)
[0m[1;32m    217[0m [0;34m[0m[0m

[0;31mPolynomialError[0m: cos(theta) contains an element of the set of generators.

During handling of the above exception, another exception occurred:

[0;31mNonlinearError[0m                            Traceback (most recent call last)
[0;32m<ipython-input-18-6ed066c8a656>[0m in [0;36m<module>[0;34m[0m
[1;32m      1[0m [0meq2[0m [0;34m=[0m [0;34m[[0m[0mEq[0m[0;34m([0m[0mcoef[0m[0;34m,[0m[0;36m0[0m[0;34m)[0m [0;32mfor[0m [0mcoef[0m [0;32min[0m [0mcoefs[0m[0;34m][0m[0;34m[0m[0;34m[0m[0m
[0;32m----> 2[0;31m [0msolution[0m[0;34m,[0m [0;34m=[0m [0mlinsolve[0m[0;34m([0m[0meq2[0m[0;34m,[0m[0;34m([0m[0mi0[0m[0;34m,[0m[0mtheta[0m[0;34m)[0m[0;34m)[0m[0;34m[0m[0;34m[0m[0m
[0m
[0;32m/Library/Frameworks/Python.framework/Versions/3.7/lib/python3.7/site-packages/sympy-1.7.1-py3.7.egg/sympy/solvers/solveset.py[0m in [0;36mlinsolve[0;34m(system, *symbols)[0m
[1;32m   2640[0m             [0;32mexcept[0m [0mPolynomialError[0m [0;32mas[0m [0mexc[0m[0;34m:[0m[0;34m[0m[0;34m[0m[0m
[1;32m   2641[0m                 [0;31m# e.g. cos(x) contains an element of the set of generators[0m[0;34m[0m[0;34m[0m[0;34m[0m[0m
[0;32m-> 2642[0;31m                 [0;32mraise[0m [0mNonlinearError[0m[0;34m([0m[0mstr[0m[0;34m([0m[0mexc[0m[0;34m)[0m[0;34m)[0m[0;34m[0m[0;34m[0m[0m
[0m[1;32m   2643[0m [0;34m[0m[0m
[1;32m   2644[0m             [0;32mtry[0m[0;34m:[0m[0;34m[0m[0;34m[0m[0m

[0;31mNonlinearError[0m: cos(theta) contains an element of the set of generators.
NonlinearError: cos(theta) contains an element of the set of generators.

